<?xml version="1.0"?>

<robot xmlns:xacro="http://ros.org/wiki/xacro">

	<xacro:macro name="lift_arm" params="prefix">

		<link name="${prefix}base_link">
			
			<inertial>
				<origin rpy="0 0 0" xyz="0 -0.04 0"/>
				<mass value="0.873"/>
				<inertia
					ixx="0.001751"
					ixy="0.000012"	iyy="0.000963"
					ixz="0"			iyz="0.000002"	izz="0.001730"
				/>
			</inertial>
			
			<visual>
				<origin rpy="0 0 3.142" xyz="0 0 0"/>
				<geometry>
					<mesh filename="package://lift_arm_description/models/meshes/collada_files/base.dae"/>
				</geometry>
			</visual>
			
			<collision>
				<origin rpy="0 0 3.142" xyz="0 0 0"/>
				<geometry>
					<mesh filename="package://lift_arm_description/models/meshes/collada_files/base.dae"/>
				</geometry>
				<contact_coefficients mu="1" kp="100000" kd="100000"/>
			</collision>
		</link>


		<link name="${prefix}main_arm_link">
			
			<inertial>
				<origin rpy="0 0 0" xyz="0.062 0.007 0.004"/>
				<mass value="0.108"/>
				<inertia
					ixx="0.000028"
					ixy="-0.000009"	iyy="0.000447"
					ixz="0.000031"	iyz="-0.000002"	izz="0.000453"
				/>
			</inertial>
			
			<visual>
				<origin rpy="1.571 -1.571 1.571" xyz="0 0 0"/>
				<geometry>
					<mesh filename="package://lift_arm_description/models/meshes/collada_files/main_arm.dae"/>
				</geometry>
			</visual>
			
			<collision>
				<origin rpy="1.571 -1.571 1.571" xyz="0 0 0"/>
				<geometry>
					<mesh filename="package://lift_arm_description/models/meshes/collada_files/main_arm.dae"/>
				</geometry>
				<contact_coefficients mu="1" kp="100000" kd="100000"/>
			</collision>
		</link>


		<joint name="${prefix}main_arm_joint" type="revolute">
			<parent link="${prefix}base_link"/>
			<child link="${prefix}main_arm_link"/>
			<origin xyz="0 -0.0095 0.044953" rpy="0 0 1.571"/>
			<limit lower="-1.920" upper="1.134" effort="2.236" velocity="7.480"/>
			<axis xyz="1 0 0"/>
			<dynamics damping="0.7"/>
		</joint>


		<link name="${prefix}sec_arm_link">
			
			<inertial>
				<origin rpy="0 0 0" xyz="0.021 0.000 0.009"/>
				<mass value="0.041"/>
				<inertia
					ixx="0.000005"
					ixy="-0.000000"	iyy="0.000039"
					ixz="0.000001"	iyz="-0.000000"	izz="0.000042"
				/>
			</inertial>
			
			<visual>
				<origin rpy="1.571 0 1.571" xyz="0 0 0"/>
				<geometry>
					<mesh filename="package://lift_arm_description/models/meshes/collada_files/sec_arm.dae"/>
				</geometry>
			</visual>
			
			<collision>
				<origin rpy="1.571 0 1.571" xyz="0 0 0"/>
				<geometry>
					<mesh filename="package://lift_arm_description/models/meshes/collada_files/sec_arm.dae"/>
				</geometry>
				<contact_coefficients mu="1" kp="100000" kd="100000"/>
			</collision>
		</link>


		<joint name="${prefix}sec_arm_joint" type="revolute">
			<parent link="${prefix}base_link"/>
			<child link="${prefix}sec_arm_link"/>
			<origin xyz="0 0.0095 0.044953" rpy="0 0 1.571"/>
			<limit lower="-0.436" upper="2.531" effort="2.236" velocity="7.480"/>
			<axis xyz="1 0 0"/>
			<dynamics damping="0.7"/>
		</joint>


		<link name="${prefix}strut_link">">
			
			<inertial>
				<origin rpy="0 0 0" xyz="0.080 0 0.003"/>
				<mass value="0.007"/>
				<inertia
					ixx="0.000048"
					ixy="-0.00000"	iyy="0.000018"
					ixz="0.00000"	iyz="-0.00000"	izz="0.000018"
				/>
			</inertial>
			
			<visual>
				<origin rpy="1.571 0 1.571" xyz="0 0 0"/>
				<geometry>
					<mesh filename="package://lift_arm_description/models/meshes/collada_files/strut.dae"/>
				</geometry>
			</visual>
			
			<collision>
				<origin rpy="1.571 0 1.571" xyz="0 0 0"/>
				<geometry>
					<mesh filename="package://lift_arm_description/models/meshes/collada_files/strut.dae"/>
				</geometry>
				<contact_coefficients mu="1" kp="100000" kd="100000"/>
			</collision>
		</link>


		<joint name="${prefix}strut_joint_lower" type="continuous">
			<parent link="${prefix}sec_arm_link"/>
			<child link="${prefix}strut_link"/>
			<origin xyz="0.006 0.09 0" rpy="0 0 0"/>
			<axis xyz="1 0 0"/>
		</joint>


		<link name="${prefix}upper_arm_link">
			
			<inertial>
				<origin rpy="0 0 0" xyz="-0.081 0.024 -0.006"/>
				<mass value="0.112"/>
				<inertia
					ixx="0.000036"
					ixy="0.000055"	iyy="0.000624"
					ixz="-0.000063"	iyz="0.000007"	izz="0.000614"
				/>
			</inertial>
			
			<visual>
				<origin rpy="1.571 0 1.571" xyz="0 0 0"/>
				<geometry>
					<mesh filename="package://lift_arm_description/models/meshes/collada_files/upper_arm.dae"/>
				</geometry>
			</visual>
			
			<collision>
				<origin rpy="1.571 0 1.571" xyz="0 0 0"/>
				<geometry>
					<mesh filename="package://lift_arm_description/models/meshes/collada_files/upper_arm.dae"/>
				</geometry>
				<contact_coefficients mu="1" kp="100000" kd="100000"/>
			</collision>
		</link>


		<joint name="${prefix}upper_arm_joint" type="revolute">
			<parent link="${prefix}main_arm_link"/>
			<child link="${prefix}upper_arm_link"/>
			<origin xyz="0.0095 0 0.18" rpy="0 0 0"/>
			<limit lower="-0.873" upper="1.484" effort="2.236" velocity="7.480"/>
			<axis xyz="1 0 0"/>
			<dynamics damping="0.7"/>
		</joint>


		<link name="${prefix}rack_link">
			
			<inertial>
				<origin rpy="0 0 0" xyz="0.130 0.001 0.000"/>
				<mass value="0.026"/>
				<inertia
					ixx="0.000000"
					ixy="-0.000001"	iyy="0.000241"
					ixz="0.000000"	iyz="0.000000"	izz="0.000241"
				/>
			</inertial>
			
			<visual>
				<origin rpy="1.571 0 3.1415" xyz="0 0 0"/>
				<geometry>
					<mesh filename="package://lift_arm_description/models/meshes/collada_files/rack.dae"/>
				</geometry>
			</visual>
			
			<collision>
				<origin rpy="1.571 0 3.1415" xyz="0 0 0"/>
				<geometry>
					<mesh filename="package://lift_arm_description/models/meshes/collada_files/rack.dae"/>
				</geometry>
				<contact_coefficients mu="1" kp="100000" kd="100000"/>
			</collision>
		</link>


		<joint name="${prefix}rack_joint" type="prismatic">
			<parent link="${prefix}upper_arm_link"/>
			<child link="${prefix}rack_link"/>
			<origin xyz="0 -0.30 0.033" rpy="0 0 -1.571"/>
			<limit lower="-0.1" upper="0.15" effort="3.43" velocity="0.0314"/>
			<axis xyz="1 0 0"/>
		</joint>
		
		

		
		<link name="${prefix}end_effector_link"/>

		<joint name="${prefix}enef_joint" type="fixed">
			<parent link="${prefix}rack_link"/>
			<child link="${prefix}end_effector_link"/>
			<origin xyz="0.02 0 0" rpy="0 0 0"/>
		</joint>
		

		
		
		<transmission name="${prefix}tran1">
			<type>transmission_interface/SimpleTransmission</type>
			<joint name="${prefix}main_arm_joint">
				<hardwareInterface>EffortJointInterface</hardwareInterface>
			</joint>
			<actuator name="${prefix}servo1">
				<hardwareInterface>EffortJointInterface</hardwareInterface>
				<mechanicalReduction>1</mechanicalReduction>
			</actuator>
		</transmission>
		
		<transmission name="${prefix}tran2">
			<type>transmission_interface/SimpleTransmission</type>
			<joint name="${prefix}upper_arm_joint">
				<hardwareInterface>EffortJointInterface</hardwareInterface>
			</joint>
			<actuator name="${prefix}servo2">
				<hardwareInterface>EffortJointInterface</hardwareInterface>
				<mechanicalReduction>1</mechanicalReduction>
			</actuator>
		</transmission>
		
		<transmission name="${prefix}tran3">
			<type>transmission_interface/SimpleTransmission</type>
			<joint name="${prefix}rack_joint">
				<hardwareInterface>EffortJointInterface</hardwareInterface>
			</joint>
			<actuator name="${prefix}stepper">
				<hardwareInterface>EffortJointInterface</hardwareInterface>
				<mechanicalReduction>1</mechanicalReduction>
			</actuator>
		</transmission>


	</xacro:macro>

</robot>
